<?xml version='1.0'?>

<!-- call xacro liberary-->
<robot xmlns:xacro="http://www.ros.org/wiki/xacro" name="my_robot">

    <!-- to include other files in a xacro-->
<xacro:include filename="$(find my_robot)/urdf/plgins.gazebo"/>
<xacro:include filename="$(find my_robot)/urdf/diff_drive.gazebo"/>

                <!-- xacro NOTES-->
<!-- to use xacro properties:-->
<!-- <xacro:property name="the_radius" value="2.1" />
<geometry type="cylinder" radius="${the_radius}"" /> -->
            <!-- to use xacro macro:-->
<!-- macro is like creating a function and passing parameters to it-->
<!-- name, x, y and z are the parameters to be passed-->

<xacro:macro name="left_wheel" params="name x y z">

    <link name="${name}_wheel">
        <inertial>
            <origin xyz="0.0 0.0 0.0" rpy="0.0 0.0 0.0"/>
            <mass value="2.8498940e-02" />
            <inertia ixx="1.1175580e-05" ixy="-4.2369783e-11" ixz="-5.9381719e-09"
                     iyy="1.1192413e-05" iyz="-1.4400107e-11"
                     izz="2.0712558e-05" />
        </inertial>

        <visual name="">
            <origin xyz="0.0 0.0 0.0" rpy="0.0 0.0 0.0"/>
            <!-- make sure of the scale!!-->
            <!-- <geometry>
                <mesh filename="package://my_robot/meshes/left_tire.stl" 
                      scale="0.005 0.005 0.005"/>
            </geometry> -->
            <geometry>
                <mesh filename="package://my_robot/meshes/left_tire.stl" 
                scale="0.005 0.005 0.005"/>
            </geometry> 
        </visual>

        <collision name='collision_${name}_wheel'>
            <origin xyz="0.0 0.0 0.0" rpy="0.0 0.0 0.0"/>
    
        </collision>
    </link>

    <joint name="${name}_joint" type="continuous"> 
        <origin xyz="${x} ${y} ${z}" rpy="0.0 0.0 0.0"/>
        <parent link="base_link"/>
        <child link="${name}_wheel"/>
        <axis xyz=" 0.0 -1.0 0.0"/>
    </joint>

</xacro:macro>
<xacro:macro name="right_wheel" params="name x y z">

    <link name="${name}_wheel">
        <inertial>
            <origin xyz="0.0 0.0 0.0" rpy="0.0 0.0 0.0"/>
            <mass value="2.8498940e-02" />
            <inertia ixx="1.1175580e-05" ixy="-4.2369783e-11" ixz="-5.9381719e-09"
                     iyy="1.1192413e-05" iyz="-1.4400107e-11"
                     izz="2.0712558e-05" />
        </inertial>

        <visual name="">
            <origin xyz="0.0 0.0 0.0" rpy="0.0 0.0 0.0"/>
            <!-- make sure of the scale!!-->
            <geometry>
                <mesh filename="package://my_robot/meshes/right_tire.stl" 
                      scale="0.005 0.005 0.005"/>
            </geometry>
        </visual>

        <collision name='collision_${name}_wheel'>
            <origin xyz="0.0 0.0 0.0" rpy="0.0 0.0 0.0"/>
        <geometry>
                    <cylinder radius="0.01" length="0.05"/>
        </geometry>      
        </collision>
    </link>

    <joint name="${name}_joint" type="continuous"> 
        <origin xyz="${x} ${y} ${z}" rpy="0.0 0.0 0.0"/>
        <parent link="base_link"/>
        <child link="${name}_wheel"/>
        <axis xyz="0.0 -1.0 0.0"/>
    </joint>

</xacro:macro>

    <link name="base_footprint"></link>

    <link name="base_link">
        <inertial>
            <origin xyz="0.0 0.0 0.0" rpy="0.0 0.0 0.0"/>
            <mass value="20.0"/>
            <inertia ixx="1" ixy="0.0" ixz="0.0" iyy="1.3" iyz="0.0" izz="1"/>
        </inertial>

        <visual name="baseLink_visual">
            <origin xyz="0.0 0.0 0.0" rpy="0.0 0.0 0.0"/>
            <geometry>
                <box size="0.8 0.40 0.10"/>
            </geometry>
        </visual>

        <collision name='collision'>
            <origin xyz="0.0 0.0 0.0" rpy="0.0 0.0 0.0"/>
            <geometry>
               <box size="0.8 0.40 0.10"/>
            </geometry>
        </collision>
    </link>

    <joint name="base_with_ground_joint" type="fixed">
        <origin xyz="0.0 0.0 0.18" rpy="0.0 0.0 0.0"/>
        <parent link="base_footprint"/>
        <child link="base_link"/>
        <axis xyz="0.0 0.0 0.0"/>
    </joint>

    <xacro:right_wheel name="front_right" x="0.28" y="-0.25" z="0.115"/>
    <xacro:left_wheel name="front_left"  x="0.28" y="0.25" z="0.115"/>
    <xacro:right_wheel name="rear_right"  x="-0.28" y="-0.25" z="0.115"/>
    <xacro:left_wheel name="rear_left"   x="-0.28" y="0.25" z="0.115"/>

                    
                    <!-- camera -->
                    
   <link name="camera_link">
        <collision>
            <origin xyz="0 0 0" rpy="0 0 0"/>
            <geometry>
                <box size="0.05 0.1 0.05"/>
            </geometry>
        </collision>
                    
        <visual>
            <origin xyz="0 0 0" rpy="0 0 0"/>
            <geometry>
                <box size="0.05 0.1 0.05"/>
            </geometry>
           <material name="red"/>
        </visual>
                    
        <inertial>
        <mass value="1e-5" />
        <origin xyz="0 0 0" rpy="0 0 0"/>
        <inertia ixx="1e-6" ixy="0" ixz="0" iyy="1e-6" iyz="0" izz="1e-6" />
        </inertial>
   </link>
  
    <joint name="camera_joint" type="fixed">
        <axis xyz="0 1 0" />
        <origin xyz="0.425 0 0.18" rpy="0 0 0"/>
        <parent link="base_link"/>
        <child link="camera_link"/>
    </joint>

  <!-- Hokuyo Laser -->

  <joint name="hokuyo_joint" type="fixed">
    <origin xyz="0.35 0 0.26" rpy="0 0 0"/>
    <parent link="base_link"/>
    <child link="hokuyo_link"/>
  </joint>

  <link name="hokuyo_link">
    <collision>
      <origin xyz="0 0 0" rpy="0 0 0"/>
      <geometry>
    <box size="0.01 0.01 0.01"/>
      </geometry>
    </collision>

    <visual>
      <origin xyz="0 0 0" rpy="0 0 0"/>
      <geometry>
        <mesh filename="package://my_robot/meshes/hokuyo.dae"/>
      </geometry>
    </visual>

    <inertial>
      <mass value="1e-5" />
      <origin xyz="0 0 0" rpy="0 0 0"/>
      <inertia ixx="1e-6" ixy="0" ixz="0" iyy="1e-6" iyz="0" izz="1e-6" />
    </inertial>
  </link>    
</robot>
